<?xml version="1.0"?>
<robot xmlns:xacro="http://www.ros.org/wiki/xacro"  name="robot">

    <link name="base_link">

    </link>

    <!-- BASE_FOOTPRINT LINK -->

    <joint name="base_footprint_joint" type="fixed">
        <parent link="base_link"/>
        <child link="base_footprint"/>
        <origin xyz="0 0 0" rpy="0 0 0"/>
    </joint>

    <link name="base_footprint">
    </link>

    <!-- CHASSIS LINK -->

    <joint name="chassis_joint" type="fixed">
        <parent link="base_link"/>
        <child link="chassis_link"/>
        <origin xyz="0 0 0"/>
    </joint>

      <link
    name="chassis_link">
    <inertial>
      <origin
        xyz="0.00196170680937007 -0.0868228015469567 -0.0309340370914814"
        rpy="0 0 0" />
      <mass
        value="0.458411450979246" />
      <inertia
        ixx="0.000542871589384656"
        ixy="1.69749191833194E-07"
        ixz="9.16830524623752E-08"
        iyy="0.000657663684621469"
        iyz="-3.00802775983815E-06"
        izz="0.00108671668484761" />
    </inertial>
    <visual>
      <origin
        xyz="0 0 0"
        rpy="0 0 0" />
      <geometry>
          <mesh filename="package://tars_amr_sim/meshes/base_link.STL" />
      </geometry>
      <material
        name="">
        <color
          rgba="1 1 1 1" />
      </material>
    </visual>
    <collision>
      <origin
        xyz="0 0 0"
        rpy="0 0 0" />
      <geometry>
        <mesh
          filename="package://tars_amr_sim/meshes/base_link.STL" />
      </geometry>
    </collision>
  </link>
  <link
    name="Left_wheel_link">
    <inertial>
      <origin
        xyz="-0.00784940612576868 4.28642898509662E-05 -9.31058257115994E-06"
        rpy="0 0 0" />
      <mass
        value="0.0274335863022573" />
      <inertia
        ixx="1.13862377406955E-05"
        ixy="-4.63211244042856E-15"
        ixz="9.35749928836235E-15"
        iyy="6.00789413976309E-06"
        iyz="-1.82633067451514E-08"
        izz="6.02049780409006E-06" />
    </inertial>
    <visual>
      <origin
        xyz="0 0 0"
        rpy="0 0 0" />
      <geometry>
        <mesh
          filename="package://tars_amr_sim/meshes/Left_wheel_link.STL" />
      </geometry>
      <material
        name="">
        <color
          rgba="1 1 1 1" />
      </material>
    </visual>
    <collision>
      <origin
        xyz="0 0 0"
        rpy="0 0 0" />
      <geometry>
        <mesh
          filename="package://tars_amr_sim/meshes/Left_wheel_link.STL" />
      </geometry>
    </collision>
  </link>
  <joint
    name="Left_wheel_link_joint"
    type="continuous">
    <origin
      xyz="0.0586 -0.08 -0.035"
      rpy="0 0 0" />
    <parent
      link="base_link" />
    <child
      link="Left_wheel_link" />
    <axis
      xyz="1 0 0" />
  </joint>
  <link
    name="Right_wheel_link">
    <inertial>
      <origin
        xyz="-0.00784940612576874 4.28642898509385E-05 -9.31058257162831E-06"
        rpy="0 0 0" />
      <mass
        value="0.0274335863022572" />
      <inertia
        ixx="1.13862377406954E-05"
        ixy="-4.63212894995761E-15"
        ixz="9.3575734507046E-15"
        iyy="6.00789413976302E-06"
        iyz="-1.82633067450594E-08"
        izz="6.02049780409007E-06" />
    </inertial>
    <visual>
      <origin
        xyz="0 0 0"
        rpy="0 0 0" />
      <geometry>
        <mesh
          filename="package://tars_amr_sim/meshes/Right_wheel_link.STL" />
      </geometry>
      <material
        name="">
        <color
          rgba="1 1 1 1" />
      </material>
    </visual>
    <collision>
      <origin
        xyz="0 0 0"
        rpy="0 0 0" />
      <geometry>
        <mesh
          filename="package://tars_amr_sim/meshes/Right_wheel_link.STL" />
      </geometry>
    </collision>
  </link>
  <joint
    name="Right_wheel_link_joint"
    type="continuous">
    <origin
      xyz="-0.0586 -0.08 -0.035"
      rpy="0 0 0" />
    <parent
      link="base_link" />
    <child
      link="Right_wheel_link" />
    <axis
      xyz="1 0 0" />
  </joint>
   <link
    name="Link_pair_1">
    <inertial>
      <origin
        xyz="0.0122273760193206 -3.21860593732737E-14 0.0079914509294892"
        rpy="0 0 0" />
      <mass
        value="0.00369780273035827" />
      <inertia
        ixx="6.11514536437229E-08"
        ixy="-5.820653179875E-24"
        ixz="2.01266652952978E-24"
        iyy="6.25046675936164E-07"
        iyz="-7.7711533483172E-25"
        izz="6.70790618203394E-07" />
    </inertial>
    <visual>
      <origin
        xyz="0 0 0"
        rpy="0 0 0" />
      <geometry>
        <mesh
          filename="package://tars_amr_sim/meshes/link_pair_1.STL" />
      </geometry>
      <material
        name="">
        <color
          rgba="1 1 1 1" />
      </material>
    </visual>
    <collision>
      <origin
        xyz="0 0 0"
        rpy="0 0 0" />
      <geometry>
        <mesh
          filename="package://tars_amr_sim/meshes/link_pair_1.STL" />
      </geometry>
    </collision>
  </link>
  <joint
    name="Link_pair_1_joint"
    type="continuous">
    <origin
      xyz="0.087 -0.0695 -0.018"
      rpy="1.5708 0 0" />
    <parent
      link="base_link" />
    <child
      link="Link_pair_1" />
    <axis
      xyz="0 0 1" />
  </joint>
  <link
    name="big_triangle_1">
    <inertial>
      <origin
        xyz="0.0195755407568848 -0.00278501208050816 0.0180107799944266"
        rpy="0 0 0" />
      <mass
        value="0.074547880950281" />
      <inertia
        ixx="5.43833714550981E-05"
        ixy="-1.64485303519001E-06"
        ixz="1.46443358252426E-06"
        iyy="6.94150724784236E-05"
        iyz="-7.5546027497944E-07"
        izz="2.41737178555845E-05" />
    </inertial>
    <visual>
      <origin
        xyz="0 0 0"
        rpy="0 0 0" />
      <geometry>
        <mesh
          filename="package://tars_amr_sim/meshes/big_triangle_link.STL" />
      </geometry>
      <material
        name="">
        <color
          rgba="1 1 1 1" />
      </material>
    </visual>
    <collision>
      <origin
        xyz="0 0 0"
        rpy="0 0 0" />
      <geometry>
        <mesh
          filename="package://tars_amr_sim/meshes/big_triangle_link.STL" />
      </geometry>
    </collision>
  </link>
  <joint
    name="big_triangle_1_joint"
    type="continuous">
    <origin
      xyz="0.0365000000000118 0 -0.048"
      rpy="0.0087266462599717 0 0" />
    <parent
      link="Link_pair_1" />
    <child
      link="big_triangle_1" />
    <axis
      xyz="0 0.00872653549837413 0.999961923064171" />
  </joint>
  <link
    name="link_1">
    <inertial>
      <origin
        xyz="0.00925000000000004 -3.56659146660832E-15 -6.93889390390723E-17"
        rpy="0 0 0" />
      <mass
        value="0.000418829254091884" />
      <inertia
        ixx="1.72374656454096E-09"
        ixy="2.13344257577636E-22"
        ixz="2.0524418948972E-23"
        iyy="2.05758913679062E-08"
        iyz="7.09745245672708E-25"
        izz="2.16713940513094E-08" />
    </inertial>
    <visual>
      <origin
        xyz="0 0 0"
        rpy="0 0 0" />
      <geometry>
        <mesh
          filename="package://tars_amr_sim/meshes/link_1.STL" />
      </geometry>
      <material
        name="">
        <color
          rgba="0.858823529411765 0.858823529411765 0.858823529411765 0.1" />
      </material>
    </visual>
    <collision>
      <origin
        xyz="0 0 0"
        rpy="0 0 0" />
      <geometry>
        <mesh
          filename="package://tars_amr_sim/meshes/link_1.STL" />
      </geometry>
    </collision>
  </link>
  <joint
    name="link_1_joint"
    type="continuous">
    <origin
      xyz="0.051256 -0.01171 0.033266"
      rpy="-0.012341 -0.78536 0.0087263" />
    <parent
      link="big_triangle_1" />
    <child
      link="link_1" />
    <axis
      xyz="0 0 1" />
  </joint>
  <link
    name="big_non_actuated_triangle_mirror">
    <inertial>
      <origin
        xyz="0.030919243545911 0.00878668880203192 -0.0148475592469524"
        rpy="0 0 0" />
      <mass
        value="0.0721297540054504" />
      <inertia
        ixx="5.39632726368139E-05"
        ixy="1.56283388931883E-06"
        ixz="-1.44322942163294E-06"
        iyy="6.91067908994078E-05"
        iyz="5.02154368175076E-08"
        izz="2.3503289928344E-05" />
    </inertial>
    <visual>
      <origin
        xyz="0 0 0"
        rpy="0 0 0" />
      <geometry>
        <mesh
          filename="package://tars_amr_sim/meshes/big_non_actuated_triangle_mirror.STL" />
      </geometry>
      <material
        name="">
        <color
          rgba="1 1 1 1" />
      </material>
    </visual>
    <collision>
      <origin
        xyz="0 0 0"
        rpy="0 0 0" />
      <geometry>
        <mesh
          filename="package://tars_amr_sim/meshes/big_non_actuated_triangle_mirror.STL" />
      </geometry>
    </collision>
  </link>
  <joint
    name="big_non_actuated_triangle_mirror_joint"
    type="continuous">
    <origin
      xyz="0.0185000000000003 0 0"
      rpy="-0.0174516313869211 -0.785283940562994 0.0123396187386001" />
    <parent
      link="link_1" />
    <child
      link="big_non_actuated_triangle_mirror" />
    <axis
      xyz="0.707026008833154 -0.0123409498970772 0.707079856727016" />
  </joint>

</robot>